Workbook

Sheet League Table
A1: MARLOW DUKES 2026
B2: 46028 | C2: 46035 | D2: 46042 | E2: 46049 | F2: 46056 | G2: 46063 | H2: 46070 | I2: 46077 | J2: 46084 | K2: 46091 | L2: 46098 | M2: 46105 | N2: 46112 | O2: 46119 | P2: 46126 | Q2: 46133 | R2: 46140 | S2: 46147 | T2: 46154 | U2: 46161 | V2: 46168 | W2: 46175 | X2: 46182 | Y2: 46189 | Z2: 46196 | AA2: 46203 | AB2: 46210 | AC2: 46217 | AD2: 46224 | AE2: 46231 | AF2: 46238 | AG2: 46245 | AH2: 46252 | AI2: 46259 | AJ2: 46266 | AK2: 46273 | AL2: 46280 | AM2: 46287 | AN2: 46294 | AO2: 46301 | AP2: 46308 | AQ2: 46315 | AR2: 46322 | AS2: 46329 | AT2: 46336 | AU2: 46343 | AV2: 46350 | AW2: 46357 | AX2: 46364
A3: PLAYER | B3: WK 1 | C3: WK 2 | D3: WK 3 | E3: WK 4 | F3: WK 5 | G3: WK 6 | H3: WK 7 | I3: WK 8 | J3: WK 9 | K3: WK 10 | L3: WK 11 | M3: WK 12 | N3: WK 13 | O3: WK 14 | P3: WK 15 | Q3: WK 16 | R3: WK 17 | S3: WK 18 | T3: WK 19 | U3: WK 20 | V3: WK 21 | W3: WK 22 | X3: WK 23 | Y3: WK 24 | Z3: WK 25 | AA3: WK 26 | AB3: WK 27 | AC3: WK 28 | AD3: WK 29 | AE3: WK 30 | AF3: WK 31 | AG3: WK 32 | AH3: WK 33 | AI3: WK 34 | AJ3: WK 35 | AK3: WK 36 | AL3: WK 37 | AM3: WK 38 | AN3: WK 39 | AO3: WK 40 | AP3: WK 41 | AQ3: WK 42 | AR3: WK 43 | AS3: WK 44 | AT3: WK 45 | AU3: WK 46 | AV3: WK 47 | AW3: WK 48 | AX3: WK 49 | AY3: POSITION | AZ3: PLAYED | BA3: WON | BB3: DRAWN | BC3: LOST | BD3: PTS | BE3: G/D | BF3: %
A5: POSH CHRIS | C5: 0 | D5: 2 | E5: 0 | F5: -2 | G5: -2 | H5: 1 | I5: 1 | J5: 1 | K5: 0 | L5: 4 | M5: 2 | N5: 2 | O5: 0 | P5: 5 | Q5: 4 | R5: 3 | T5: 0 | U5: 0 | V5: 0 | Y5: -1 | AA5: 3 | AB5: 2 | AC5: -2 | AD5: 0 | AE5: 1 | AF5: -5 | AY5: 1 | AZ5: =COUNT(B5:AX5) -> 26 | BA5: =COUNTIF($B5:$AX5, ">=1") -> 13 | BB5: =COUNTIF($B5:$AX5, "0") -> 8 | BC5: =COUNTIF($B5:$AX5, "<0") -> 5 | BD5: =SUM(BA5*3)+BB5 -> 47 | BE5: =SUM(B5:AX5) -> 19 | BF5: =SUM(BA5*3+BB5*1)/SUM(AZ5*3) -> 0.6025641
A6: IAN | D6: 2 | E6: 0 | F6: 2 | G6: 2 | H6: 1 | I6: -1 | J6: -1 | K6: 0 | L6: 4 | N6: -2 | O6: 0 | P6: 5 | Q6: 4 | V6: 0 | W6: 0 | Y6: 1 | AB6: 2 | AC6: 2 | AD6: 0 | AE6: -1 | AF6: -5 | AY6: 2 | AZ6: =COUNT(B6:AX6) -> 21 | BA6: =COUNTIF($B6:$AX6, ">=1") -> 10 | BB6: =COUNTIF($B6:$AX6, "0") -> 6 | BC6: =COUNTIF($B6:$AX6, "<0") -> 5 | BD6: =SUM(BA6*3)+BB6 -> 36 | BE6: =SUM(B6:AX6) -> 15 | BF6: =SUM(BA6*3+BB6*1)/SUM(AZ6*3) -> 0.57142857
A7: KERMIT | C7: 0 | D7: -2 | E7: 0 | F7: 2 | G7: 2 | H7: -1 | I7: 1 | J7: 1 | K7: 0 | N7: 2 | O7: 0 | P7: 5 | Q7: 4 | R7: -3 | T7: 0 | U7: 0 | Y7: 1 | AA7: -3 | AB7: 2 | AD7: 0 | AE7: -1 | AY7: 3 | AZ7: =COUNT(B7:AX7) -> 21 | BA7: =COUNTIF($B7:$AX7, ">=1") -> 9 | BB7: =COUNTIF($B7:$AX7, "0") -> 7 | BC7: =COUNTIF($B7:$AX7, "<0") -> 5 | BD7: =SUM(BA7*3)+BB7 -> 34 | BE7: =SUM(B7:AX7) -> 10 | BF7: =SUM(BA7*3+BB7*1)/SUM(AZ7*3) -> 0.53968254
A8: BRUCE | C8: 0 | D8: 2 | E8: 0 | G8: -2 | H8: -1 | I8: 1 | J8: -1 | K8: 0 | L8: -4 | M8: -2 | N8: -2 | P8: -5 | Q8: -4 | R8: 3 | T8: 0 | V8: 0 | W8: 0 | Y8: 1 | AA8: 3 | AB8: 2 | AC8: 2 | AD8: 0 | AE8: 1 | AF8: -5 | AY8: 4 | AZ8: =COUNT(B8:AX8) -> 24 | BA8: =COUNTIF($B8:$AX8, ">=1") -> 8 | BB8: =COUNTIF($B8:$AX8, "0") -> 7 | BC8: =COUNTIF($B8:$AX8, "<0") -> 9 | BD8: =SUM(BA8*3)+BB8 -> 31 | BE8: =SUM(B8:AX8) -> -11 | BF8: =SUM(BA8*3+BB8*1)/SUM(AZ8*3) -> 0.43055556
A9: ARTIST | D9: 2 | I9: -1 | J9: 1 | K9: 0 | L9: -4 | M9: -2 | N9: -2 | O9: 0 | P9: 5 | Q9: 4 | T9: 0 | Y9: 1 | AA9: -3 | AB9: 2 | AC9: 2 | AD9: 0 | AE9: -1 | AF9: 5 | AY9: 5 | AZ9: =COUNT(B9:AX9) -> 18 | BA9: =COUNTIF($B9:$AX9, ">=1") -> 8 | BB9: =COUNTIF($B9:$AX9, "0") -> 4 | BC9: =COUNTIF($B9:$AX9, "<0") -> 6 | BD9: =SUM(BA9*3)+BB9 -> 28 | BE9: =SUM(B9:AX9) -> 9 | BF9: =SUM(BA9*3+BB9*1)/SUM(AZ9*3) -> 0.51851852
A10: SONES | C10: 0 | D10: -2 | E10: 0 | J10: -1 | L10: 4 | M10: -2 | N10: 2 | O10: 0 | P10: -5 | T10: 0 | U10: 0 | V10: 0 | W10: 0 | Y10: 1 | AA10: 3 | AB10: 2 | AC10: 2 | AE10: 1 | AY10: 6 | AZ10: =COUNT(B10:AX10) -> 18 | BA10: =COUNTIF($B10:$AX10, ">=1") -> 7 | BB10: =COUNTIF($B10:$AX10, "0") -> 7 | BC10: =COUNTIF($B10:$AX10, "<0") -> 4 | BD10: =SUM(BA10*3)+BB10 -> 28 | BE10: =SUM(B10:AX10) -> 5 | BF10: =SUM(BA10*3+BB10*1)/SUM(AZ10*3) -> 0.51851852
A11: CAPTAIN KIRK | C11: 0 | E11: 0 | F11: -2 | G11: 2 | H11: -1 | I11: 1 | J11: 1 | K11: 0 | O11: 0 | P11: -5 | R11: 3 | T11: 0 | U11: 0 | V11: 0 | W11: 0 | AA11: -3 | AD11: 0 | AE11: 1 | AF11: 5 | AY11: 7 | AZ11: =COUNT(B11:AX11) -> 19 | BA11: =COUNTIF($B11:$AX11, ">=1") -> 6 | BB11: =COUNTIF($B11:$AX11, "0") -> 9 | BC11: =COUNTIF($B11:$AX11, "<0") -> 4 | BD11: =SUM(BA11*3)+BB11 -> 27 | BE11: =SUM(B11:AX11) -> 2 | BF11: =SUM(BA11*3+BB11*1)/SUM(AZ11*3) -> 0.47368421
A12: PRESTON | C12: 0 | D12: 2 | E12: 0 | F12: 2 | G12: 2 | H12: -1 | I12: -1 | J12: 1 | K12: 0 | L12: -4 | M12: 2 | N12: -2 | O12: 0 | P12: 5 | Q12: 0 | R12: -3 | T12: 0 | U12: 0 | V12: 0 | W12: 0 | Y12: -1 | AA12: -3 | AB12: -2 | AC12: -2 | AY12: 8 | AZ12: =COUNT(B12:AX12) -> 24 | BA12: =COUNTIF($B12:$AX12, ">=1") -> 6 | BB12: =COUNTIF($B12:$AX12, "0") -> 9 | BC12: =COUNTIF($B12:$AX12, "<0") -> 9 | BD12: =SUM(BA12*3)+BB12 -> 27 | BE12: =SUM(B12:AX12) -> -5 | BF12: =SUM(BA12*3+BB12*1)/SUM(AZ12*3) -> 0.375
A13: SWAMPY | C13: 0 | E13: 0 | H13: 1 | J13: 1 | K13: 0 | L13: -4 | M13: 2 | N13: -2 | Q13: 4 | R13: 3 | T13: 0 | U13: 0 | V13: 0 | W13: 0 | Y13: -1 | AB13: -2 | AD13: 0 | AE13: 1 | AY13: 9 | AZ13: =COUNT(B13:AX13) -> 18 | BA13: =COUNTIF($B13:$AX13, ">=1") -> 6 | BB13: =COUNTIF($B13:$AX13, "0") -> 8 | BC13: =COUNTIF($B13:$AX13, "<0") -> 4 | BD13: =SUM(BA13*3)+BB13 -> 26 | BE13: =SUM(B13:AX13) -> 3 | BF13: =SUM(BA13*3+BB13*1)/SUM(AZ13*3) -> 0.48148148
A14: ZIGZAG | C14: 0 | E14: 0 | G14: -2 | H14: -1 | I14: -1 | J14: -1 | K14: 0 | M14: 2 | N14: 2 | O14: 0 | P14: -5 | Q14: -4 | T14: 0 | U14: 0 | V14: 0 | W14: 0 | Y14: 1 | AB14: 2 | AC14: -2 | AD14: 0 | AE14: -1 | AF14: 5 | AY14: 10 | AZ14: =COUNT(B14:AX14) -> 22 | BA14: =COUNTIF($B14:$AX14, ">=1") -> 5 | BB14: =COUNTIF($B14:$AX14, "0") -> 9 | BC14: =COUNTIF($B14:$AX14, "<0") -> 8 | BD14: =SUM(BA14*3)+BB14 -> 24 | BE14: =SUM(B14:AX14) -> -5 | BF14: =SUM(BA14*3+BB14*1)/SUM(AZ14*3) -> 0.36363636
A15: BROWN NOSE | C15: 0 | F15: 2 | G15: 2 | I15: 1 | K15: 0 | L15: 4 | M15: -2 | O15: 0 | W15: 0 | Y15: 1 | AA15: -3 | AB15: -2 | AC15: 2 | AD15: 0 | AY15: 11 | AZ15: =COUNT(B15:AX15) -> 14 | BA15: =COUNTIF($B15:$AX15, ">=1") -> 6 | BB15: =COUNTIF($B15:$AX15, "0") -> 5 | BC15: =COUNTIF($B15:$AX15, "<0") -> 3 | BD15: =SUM(BA15*3)+BB15 -> 23 | BE15: =SUM(B15:AX15) -> 5 | BF15: =SUM(BA15*3+BB15*1)/SUM(AZ15*3) -> 0.54761905
A16: FATHER TED | E16: 0 | H16: -1 | I16: -1 | J16: -1 | K16: 0 | L16: 4 | M16: 2 | O16: 0 | Q16: -4 | R16: 3 | T16: 0 | V16: 0 | W16: 0 | Y16: 1 | AB16: -2 | AC16: -2 | AE16: 1 | AY16: 12 | AZ16: =COUNT(B16:AX16) -> 17 | BA16: =COUNTIF($B16:$AX16, ">=1") -> 5 | BB16: =COUNTIF($B16:$AX16, "0") -> 6 | BC16: =COUNTIF($B16:$AX16, "<0") -> 6 | BD16: =SUM(BA16*3)+BB16 -> 21 | BE16: =SUM(B16:AX16) -> 0 | BF16: =SUM(BA16*3+BB16*1)/SUM(AZ16*3) -> 0.41176471
A17: KRYTON | C17: 0 | F17: 2 | H17: -1 | I17: 1 | L17: 4 | N17: 2 | O17: 0 | V17: 0 | W17: 0 | AB17: 2 | AD17: 0 | AE17: -1 | AY17: 13 | AZ17: =COUNT(B17:AX17) -> 12 | BA17: =COUNTIF($B17:$AX17, ">=1") -> 5 | BB17: =COUNTIF($B17:$AX17, "0") -> 5 | BC17: =COUNTIF($B17:$AX17, "<0") -> 2 | BD17: =SUM(BA17*3)+BB17 -> 20 | BE17: =SUM(B17:AX17) -> 9 | BF17: =SUM(BA17*3+BB17*1)/SUM(AZ17*3) -> 0.55555556
A18: GOBBY | C18: 0 | D18: -2 | E18: 0 | F18: -2 | G18: 2 | H18: 1 | I18: -1 | K18: 0 | L18: -4 | M18: -2 | O18: 0 | Q18: -4 | V18: 0 | W18: 0 | AA18: 3 | AB18: 2 | AD18: 0 | AE18: -1 | AF18: -5 | AY18: 14 | AZ18: =COUNT(B18:AX18) -> 19 | BA18: =COUNTIF($B18:$AX18, ">=1") -> 4 | BB18: =COUNTIF($B18:$AX18, "0") -> 7 | BC18: =COUNTIF($B18:$AX18, "<0") -> 8 | BD18: =SUM(BA18*3)+BB18 -> 19 | BE18: =SUM(B18:AX18) -> -13 | BF18: =SUM(BA18*3+BB18*1)/SUM(AZ18*3) -> 0.33333333
A19: TONY W | J19: -1 | M19: 2 | P19: 5 | Q19: 4 | V19: 0 | W19: 0 | AA19: 3 | AB19: -2 | AC19: 2 | AD19: 0 | AE19: -1 | AF19: -5 | AY19: 15 | AZ19: =COUNT(B19:AX19) -> 12 | BA19: =COUNTIF($B19:$AX19, ">=1") -> 5 | BB19: =COUNTIF($B19:$AX19, "0") -> 3 | BC19: =COUNTIF($B19:$AX19, "<0") -> 4 | BD19: =SUM(BA19*3)+BB19 -> 18 | BE19: =SUM(B19:AX19) -> 7 | BF19: =SUM(BA19*3+BB19*1)/SUM(AZ19*3) -> 0.5
A20: INSPECTOR GADGET | D20: -2 | E20: 0 | F20: 2 | H20: 1 | I20: 1 | J20: 1 | K20: 0 | L20: 4 | M20: -2 | N20: -2 | AY20: 16 | AZ20: =COUNT(B20:AX20) -> 10 | BA20: =COUNTIF($B20:$AX20, ">=1") -> 5 | BB20: =COUNTIF($B20:$AX20, "0") -> 2 | BC20: =COUNTIF($B20:$AX20, "<0") -> 3 | BD20: =SUM(BA20*3)+BB20 -> 17 | BE20: =SUM(B20:AX20) -> 3 | BF20: =SUM(BA20*3+BB20*1)/SUM(AZ20*3) -> 0.56666667
A21: DWARF | J21: -1 | K21: 0 | M21: 2 | N21: 2 | O21: 0 | R21: -3 | T21: 0 | U21: 0 | V21: 0 | Y21: 1 | AB21: -2 | AE21: -1 | AF21: 5 | AY21: 17 | AZ21: =COUNT(B21:AX21) -> 13 | BA21: =COUNTIF($B21:$AX21, ">=1") -> 4 | BB21: =COUNTIF($B21:$AX21, "0") -> 5 | BC21: =COUNTIF($B21:$AX21, "<0") -> 4 | BD21: =SUM(BA21*3)+BB21 -> 17 | BE21: =SUM(B21:AX21) -> 3 | BF21: =SUM(BA21*3+BB21*1)/SUM(AZ21*3) -> 0.43589744
A22: FLO | C22: 0 | E22: 0 | I22: 1 | L22: -4 | O22: 0 | Q22: -4 | T22: 0 | U22: 0 | V22: 0 | W22: 0 | Y22: -1 | AA22: 3 | AB22: -2 | AC22: -2 | AD22: 0 | AE22: 1 | AY22: 18 | AZ22: =COUNT(B22:AX22) -> 16 | BA22: =COUNTIF($B22:$AX22, ">=1") -> 3 | BB22: =COUNTIF($B22:$AX22, "0") -> 8 | BC22: =COUNTIF($B22:$AX22, "<0") -> 5 | BD22: =SUM(BA22*3)+BB22 -> 17 | BE22: =SUM(B22:AX22) -> -8 | BF22: =SUM(BA22*3+BB22*1)/SUM(AZ22*3) -> 0.35416667
A23: DUNCAN | C23: 0 | D23: 2 | E23: 0 | F23: -2 | G23: -2 | H23: 1 | I23: -1 | K23: 0 | L23: -4 | M23: -2 | N23: -2 | O23: 0 | Q23: -4 | T23: 0 | W23: 0 | Y23: -1 | AB23: 0 | AD23: 0 | AF23: 5 | AY23: 19 | AZ23: =COUNT(B23:AX23) -> 19 | BA23: =COUNTIF($B23:$AX23, ">=1") -> 3 | BB23: =COUNTIF($B23:$AX23, "0") -> 8 | BC23: =COUNTIF($B23:$AX23, "<0") -> 8 | BD23: =SUM(BA23*3)+BB23 -> 17 | BE23: =SUM(B23:AX23) -> -10 | BF23: =SUM(BA23*3+BB23*1)/SUM(AZ23*3) -> 0.29824561
A24: DOBBO | AC24: 2 | AD24: 0 | AE24: 1 | AF24: 5 | AY24: 20 | AZ24: =COUNT(B24:AX24) -> 4 | BA24: =COUNTIF($B24:$AX24, ">=1") -> 3 | BB24: =COUNTIF($B24:$AX24, "0") -> 1 | BC24: =COUNTIF($B24:$AX24, "<0") -> 0 | BD24: =SUM(BA24*3)+BB24 -> 10 | BE24: =SUM(B24:AX24) -> 8 | BF24: =SUM(BA24*3+BB24*1)/SUM(AZ24*3) -> 0.83333333
A25: BANKSY | D25: -2 | E25: 0 | I25: 1 | J25: 1 | P25: -5 | Q25: -4 | R25: -3 | AC25: 2 | AE25: -1 | AF25: -5 | AY25: 21 | AZ25: =COUNT(B25:AX25) -> 10 | BA25: =COUNTIF($B25:$AX25, ">=1") -> 3 | BB25: =COUNTIF($B25:$AX25, "0") -> 1 | BC25: =COUNTIF($B25:$AX25, "<0") -> 6 | BD25: =SUM(BA25*3)+BB25 -> 10 | BE25: =SUM(B25:AX25) -> -16 | BF25: =SUM(BA25*3+BB25*1)/SUM(AZ25*3) -> 0.33333333
A26: WILSON | C26: 0 | E26: 0 | G26: -2 | K26: 0 | P26: -5 | AC26: -2 | AE26: 1 | AF26: 5 | AY26: 22 | AZ26: =COUNT(B26:AX26) -> 8 | BA26: =COUNTIF($B26:$AX26, ">=1") -> 2 | BB26: =COUNTIF($B26:$AX26, "0") -> 3 | BC26: =COUNTIF($B26:$AX26, "<0") -> 3 | BD26: =SUM(BA26*3)+BB26 -> 9 | BE26: =SUM(B26:AX26) -> -3 | BF26: =SUM(BA26*3+BB26*1)/SUM(AZ26*3) -> 0.375
A27: GUEST | I27: -1 | K27: 0 | M27: 2 | N27: -2 | Y27: -1 | AA27: 3 | AC27: 0 | AD27: 0 | AF27: -5 | AY27: 23 | AZ27: =COUNT(B27:AX27) -> 9 | BA27: =COUNTIF($B27:$AX27, ">=1") -> 2 | BB27: =COUNTIF($B27:$AX27, "0") -> 3 | BC27: =COUNTIF($B27:$AX27, "<0") -> 4 | BD27: =SUM(BA27*3)+BB27 -> 9 | BE27: =SUM(B27:AX27) -> -4 | BF27: =SUM(BA27*3+BB27*1)/SUM(AZ27*3) -> 0.33333333
A28: CARLOS | C28: 0 | N28: 2 | O28: 0 | P28: 5 | R28: -3 | AY28: 24 | AZ28: =COUNT(B28:AX28) -> 5 | BA28: =COUNTIF($B28:$AX28, ">=1") -> 2 | BB28: =COUNTIF($B28:$AX28, "0") -> 2 | BC28: =COUNTIF($B28:$AX28, "<0") -> 1 | BD28: =SUM(BA28*3)+BB28 -> 8 | BE28: =SUM(B28:AX28) -> 4 | BF28: =SUM(BA28*3+BB28*1)/SUM(AZ28*3) -> 0.53333333
A29: PHANTOM | C29: 0 | F29: -2 | H29: -1 | I29: -1 | J29: -1 | K29: 0 | L29: -4 | P29: -5 | Q29: 4 | R29: -3 | V29: 0 | W29: 0 | Y29: -1 | AB29: -2 | AC29: -2 | AD29: 0 | AY29: 25 | AZ29: =COUNT(B29:AX29) -> 16 | BA29: =COUNTIF($B29:$AX29, ">=1") -> 1 | BB29: =COUNTIF($B29:$AX29, "0") -> 5 | BC29: =COUNTIF($B29:$AX29, "<0") -> 10 | BD29: =SUM(BA29*3)+BB29 -> 8 | BE29: =SUM(B29:AX29) -> -18 | BF29: =SUM(BA29*3+BB29*1)/SUM(AZ29*3) -> 0.16666667
A30: DOM | AD30: 0 | AE30: 1 | AF30: 5 | AY30: 26 | AZ30: =COUNT(B30:AX30) -> 3 | BA30: =COUNTIF($B30:$AX30, ">=1") -> 2 | BB30: =COUNTIF($B30:$AX30, "0") -> 1 | BC30: =COUNTIF($B30:$AX30, "<0") -> 0 | BD30: =SUM(BA30*3)+BB30 -> 7 | BE30: =SUM(B30:AX30) -> 6 | BF30: =SUM(BA30*3+BB30*1)/SUM(AZ30*3) -> 0.77777778
A31: GUEST 2 | I31: 1 | N31: 2 | Y31: -1 | AA31: -3 | AY31: 27 | AZ31: =COUNT(B31:AX31) -> 4 | BA31: =COUNTIF($B31:$AX31, ">=1") -> 2 | BB31: =COUNTIF($B31:$AX31, "0") -> 0 | BC31: =COUNTIF($B31:$AX31, "<0") -> 2 | BD31: =SUM(BA31*3)+BB31 -> 6 | BE31: =SUM(B31:AX31) -> -1 | BF31: =SUM(BA31*3+BB31*1)/SUM(AZ31*3) -> 0.5
A32: DITCH | R32: 3 | AD32: 0 | AY32: 28 | AZ32: =COUNT(B32:AX32) -> 2 | BA32: =COUNTIF($B32:$AX32, ">=1") -> 1 | BB32: =COUNTIF($B32:$AX32, "0") -> 1 | BC32: =COUNTIF($B32:$AX32, "<0") -> 0 | BD32: =SUM(BA32*3)+BB32 -> 4 | BE32: =SUM(B32:AX32) -> 3 | BF32: =SUM(BA32*3+BB32*1)/SUM(AZ32*3) -> 0.66666667
A33: TOY BOY | D33: 2 | E33: 0 | AY33: 29 | AZ33: =COUNT(B33:AX33) -> 2 | BA33: =COUNTIF($B33:$AX33, ">=1") -> 1 | BB33: =COUNTIF($B33:$AX33, "0") -> 1 | BC33: =COUNTIF($B33:$AX33, "<0") -> 0 | BD33: =SUM(BA33*3)+BB33 -> 4 | BE33: =SUM(B33:AX33) -> 2 | BF33: =SUM(BA33*3+BB33*1)/SUM(AZ33*3) -> 0.66666667
A34: CARZOLA | G34: -2 | M34: 2 | N34: -2 | V34: 0 | AY34: 30 | AZ34: =COUNT(B34:AX34) -> 4 | BA34: =COUNTIF($B34:$AX34, ">=1") -> 1 | BB34: =COUNTIF($B34:$AX34, "0") -> 1 | BC34: =COUNTIF($B34:$AX34, "<0") -> 2 | BD34: =SUM(BA34*3)+BB34 -> 4 | BE34: =SUM(B34:AX34) -> -2 | BF34: =SUM(BA34*3+BB34*1)/SUM(AZ34*3) -> 0.33333333
A35: STEPTOE | W35: 0 | AA35: -3 | AB35: -2 | AC35: -2 | AD35: 0 | AY35: 31 | AZ35: =COUNT(B35:AX35) -> 5 | BA35: =COUNTIF($B35:$AX35, ">=1") -> 0 | BB35: =COUNTIF($B35:$AX35, "0") -> 2 | BC35: =COUNTIF($B35:$AX35, "<0") -> 3 | BD35: =SUM(BA35*3)+BB35 -> 2 | BE35: =SUM(B35:AX35) -> -7 | BF35: =SUM(BA35*3+BB35*1)/SUM(AZ35*3) -> 0.13333333
A36: MAMAS | C36: 0 | D36: -2 | E36: 0 | F36: -2 | AE36: -1 | AF36: -5 | AY36: 32 | AZ36: =COUNT(B36:AX36) -> 6 | BA36: =COUNTIF($B36:$AX36, ">=1") -> 0 | BB36: =COUNTIF($B36:$AX36, "0") -> 2 | BC36: =COUNTIF($B36:$AX36, "<0") -> 4 | BD36: =SUM(BA36*3)+BB36 -> 2 | BE36: =SUM(B36:AX36) -> -10 | BF36: =SUM(BA36*3+BB36*1)/SUM(AZ36*3) -> 0.11111111
A37: WOGER | AY37: 34 | AZ37: =COUNT(B37:AX37) -> 0 | BA37: =COUNTIF($B37:$AX37, ">=1") -> 0 | BB37: =COUNTIF($B37:$AX37, "0") -> 0 | BC37: =COUNTIF($B37:$AX37, "<0") -> 0 | BD37: =SUM(BA37*3)+BB37 -> 0 | BE37: =SUM(B37:AX37) -> 0 | BF37: =SUM(BA37*3+BB37*1)/SUM(AZ37*3) -> #DIV/0!
A38: VINCE | AY38: 35 | AZ38: =COUNT(B38:AX38) -> 0 | BA38: =COUNTIF($B38:$AX38, ">=1") -> 0 | BB38: =COUNTIF($B38:$AX38, "0") -> 0 | BC38: =COUNTIF($B38:$AX38, "<0") -> 0 | BD38: =SUM(BA38*3)+BB38 -> 0 | BE38: =SUM(B38:AX38) -> 0 | BF38: =SUM(BA38*3+BB38*1)/SUM(AZ38*3) -> #DIV/0!
A39: STEPHEN JEFFERY | C39: 0 | I39: -1 | AY39: 33 | AZ39: =COUNT(B39:AX39) -> 2 | BA39: =COUNTIF($B39:$AX39, ">=1") -> 0 | BB39: =COUNTIF($B39:$AX39, "0") -> 1 | BC39: =COUNTIF($B39:$AX39, "<0") -> 1 | BD39: =SUM(BA39*3)+BB39 -> 1 | BE39: =SUM(B39:AX39) -> -1 | BF39: =SUM(BA39*3+BB39*1)/SUM(AZ39*3) -> 0.16666667
A40: MARTIN PANTER | D40: -2 | AY40: 34 | AZ40: =COUNT(B40:AX40) -> 1 | BA40: =COUNTIF($B40:$AX40, ">=1") -> 0 | BB40: =COUNTIF($B40:$AX40, "0") -> 0 | BC40: =COUNTIF($B40:$AX40, "<0") -> 1 | BD40: =SUM(BA40*3)+BB40 -> 0 | BE40: =SUM(B40:AX40) -> -2 | BF40: =SUM(BA40*3+BB40*1)/SUM(AZ40*3) -> 0
A41: MOO | M41: -2 | Y41: -1 | AY41: 35 | AZ41: =COUNT(B41:AX41) -> 2 | BA41: =COUNTIF($B41:$AX41, ">=1") -> 0 | BB41: =COUNTIF($B41:$AX41, "0") -> 0 | BC41: =COUNTIF($B41:$AX41, "<0") -> 2 | BD41: =SUM(BA41*3)+BB41 -> 0 | BE41: =SUM(B41:AX41) -> -3 | BF41: =SUM(BA41*3+BB41*1)/SUM(AZ41*3) -> 0
...

Sheet Captains
A1: PLAYER | B1: P | C1: W | D1: D | E1: L | F1: GD | G1: PTS | I1: Games | J1: Ratio
A2: BRUCE | B2: 3 | C2: 2 | D2: 0 | E2: 1 | F2: 4 | G2: =SUM(C2*3)+D2 -> 6
A3: CAPTAIN KIRK | B3: 2 | C3: 2 | D3: 0 | E3: 0 | F3: 2 | G3: =SUM(C3*3)+D3 -> 6 | I3: 18 | J3: =I3/B3 -> 9
A4: IDIOT | B4: 3 | C4: 1 | D4: 2 | E4: 0 | F4: 2 | G4: =SUM(C4*3)+D4 -> 5 | I4: 24 | J4: =I4/B4 -> 8
A5: DWARF | B5: 2 | C5: 1 | D5: 1 | E5: 0 | F5: 5 | G5: =SUM(C5*3)+D5 -> 4 | I5: 27 | J5: =I5/B5 -> 13.5
A6: SONES | B6: 2 | C6: 1 | D6: 1 | E6: 0 | F6: 4 | G6: =SUM(C6*3)+D6 -> 4 | I6: 19 | J6: =I6/B6 -> 9.5
A7: BROWN NOSE | B7: 2 | C7: 1 | D7: 1 | E7: 0 | F7: 2 | G7: =SUM(C7*3)+D7 -> 4 | I7: 19 | J7: =I7/B7 -> 9.5
A8: CARZOLA | B8: 2 | C8: 1 | D8: 1 | E8: 0 | F8: 2 | G8: =SUM(C8*3)+D8 -> 4
A9: PHANTOM | B9: 3 | C9: 1 | D9: 1 | E9: 1 | F9: 2 | G9: =SUM(C9*3)+D9 -> 4
A10: DUNCAN | B10: 2 | C10: 1 | D10: 1 | E10: 0 | F10: 1 | G10: =SUM(C10*3)+D10 -> 4
A11: ARTIST | B11: 2 | C11: 1 | D11: 1 | E11: 0 | F11: 1 | G11: =SUM(C11*3)+D11 -> 4
A12: POSH CHRIS | B12: 3 | C12: 1 | D12: 1 | E12: 1 | F12: 0 | G12: =SUM(C12*3)+D12 -> 4 | I12: 25 | J12: =I12/B12 -> 8.3333333
A13: PRESTON | B13: 3 | C13: 1 | D13: 1 | E13: 1 | F13: -1 | G13: =SUM(C13*3)+D13 -> 4 | I13: 5 | J13: =I13/B13 -> 1.6666667
A14: CARLOS | B14: 1 | C14: 1 | D14: 0 | E14: 0 | F14: 2 | G14: =SUM(C14*3)+D14 -> 3 | I14: 19 | J14: =I14/B14 -> 19
A15: INSPECTOR GADGET | B15: 1 | C15: 1 | D15: 0 | E15: 0 | F15: 1 | G15: =SUM(C15*3)+D15 -> 3 | I15: 12 | J15: =I15/B15 -> 12
A16: TONY W | B16: 2 | C16: 1 | D16: 0 | E16: 1 | F16: 0 | G16: =SUM(C16*3)+D16 -> 3 | I16: 23 | J16: =I16/B16 -> 11.5
A17: BANKSY | B17: 2 | C17: 1 | D17: 0 | E17: 1 | F17: -3 | G17: =SUM(C17*3)+D17 -> 3 | I17: 19 | J17: =I17/B17 -> 9.5
A18: ZIGZAG | B18: 2 | C18: 0 | D18: 2 | E18: 0 | F18: 0 | G18: =SUM(C18*3)+D18 -> 2 | I18: 15 | J18: =I18/B18 -> 7.5
A19: WILSON | B19: 1 | C19: 0 | D19: 1 | E19: 0 | F19: 0 | G19: =SUM(C19*3)+D19 -> 1 | I19: 22 | J19: =I19/B19 -> 22
A20: GOBBY | B20: 2 | C20: 0 | D20: 1 | E20: 1 | F20: -1 | G20: =SUM(C20*3)+D20 -> 1 | I20: 14 | J20: =I20/B20 -> 7
A21: KRYTON | B21: 2 | C21: 0 | D21: 1 | E21: 1 | F21: -1 | G21: =SUM(C21*3)+D21 -> 1 | I21: 25 | J21: =I21/B21 -> 12.5
A22: MOO | B22: 1 | C22: 0 | D22: 0 | E22: 1 | F22: -2 | G22: =SUM(C22*3)+D22 -> 0 | I22: 5 | J22: =I22/B22 -> 5
A23: SWAMPY | B23: 2 | C23: 0 | D23: 0 | E23: 2 | F23: -3 | G23: =SUM(C23*3)+D23 -> 0 | I23: 12 | J23: =I23/B23 -> 6
... A25: FLO | B25: 2 | C25: 0 | D25: 0 | E25: 2 | F25: -6 | G25: =SUM(C25*3)+D25 -> 0 | I25: 25 | J25: =I25/B25 -> 12.5
A26: KERMIT | B26: 3 | C26: 0 | D26: 0 | E26: 3 | F26: -6 | G26: =SUM(C26*3)+D26 -> 0 | I26: 4
A27: MAMAS
A28: MICK | I28: 0
A29: STEPTOE
A30: TOY BOY

Sheet MOTM
A1: PLAYER | B1: WK 1 | C1: WK 2 | D1: WK 3 | E1: WK 4 | F1: WK 5 | G1: WK 6 | H1: WK 7 | I1: WK 8 | J1: WK 9 | K1: WK 10 | L1: WK 11 | M1: WK 12 | N1: WK 13 | O1: WK 14 | P1: WK 15 | Q1: WK 16 | R1: WK 17 | S1: WK 18 | T1: WK 19 | U1: WK 20 | V1: WK 21 | W1: WK 22 | X1: WK 23 | Y1: WK 24 | Z1: WK 25 | AA1: WK 26 | AB1: WK 27 | AC1: WK 28 | AD1: WK 29 | AE1: WK 30 | AF1: WK 31 | AG1: WK 32 | AH1: WK 33 | AI1: WK 34 | AJ1: WK 35 | AK1: WK 36 | AL1: WK 37 | AM1: WK 38 | AN1: WK 39 | AO1: WK 40 | AP1: WK 41 | AQ1: WK 42 | AR1: WK 43 | AS1: WK 44 | AT1: WK 45 | AU1: WK 46 | AV1: WK 47 | AW1: WK 48 | AX1: WK 49 | AY1: WK 50 | BA1: VOTES | BB1: WINS | BC1: SHARED
A3: BROWN NOSE | G3: 1 | I3: 2 | L3: 1 | O3: 2 | Y3: 2 | AB3: 1 | AC3: 1 | AD3: 1 | BA3: =SUM(B3:AY3) -> 11 | BB3: 3 | BC3: 1
A4: SWAMPY | H4: 2 | J4: 1 | N4: 2 | Q4: 1 | R4: 2 | Y4: 1 | AD4: 1 | AE4: 1 | BA4: =SUM(B4:AY4) -> 11 | BB4: 3 | BC4: 1
A5: FLO | U5: 2 | V5: 2 | AB5: 2 | AE5: 5 | BA5: =SUM(B5:AY5) -> 11 | BB5: 3
A6: ZIGZAG | E6: 1 | G6: 2 | K6: 1 | T6: 1 | U6: 1 | W6: 2 | Y6: 1 | AB6: 1 | BA6: =SUM(B6:AY6) -> 10 | BB6: 1 | BC6: 1
A7: SONES | C7: 1 | E7: 3 | L7: 1 | W7: 1 | Y7: 1 | AA7: 1 | AC7: 1 | BA7: =SUM(B7:AY7) -> 9 | BB7: 1 | BC7: 2
A8: CAPTAIN KIRK | E8: 2 | F8: 1 | H8: 1 | J8: 1 | R8: 1 | V8: 1 | AA8: 1 | AE8: 1 | BA8: =SUM(B8:AY8) -> 9 | BC8: 1
A9: POSH CHRIS | D9: 1 | H9: 1 | J9: 6 | BA9: =SUM(B9:AY9) -> 8 | BB9: 1
A10: TONY W | P10: 1 | V10: 3 | AA10: 3 | BA10: =SUM(B10:AY10) -> 7 | BB10: 2 | BC10: 1
A11: KERMIT | F11: 1 | I11: 1 | K11: 1 | Q11: 1 | T11: 2 | AB11: 1 | BA11: =SUM(B11:AY11) -> 7 | BB11: 1 | BC11: 2
A12: DWARF | K12: 2 | M12: 2 | AE12: 1 | BA12: =SUM(B12:AY12) -> 5 | BB12: 2
A13: IAN | H13: 1 | N13: 1 | O13: 1 | Q13: 1 | AC13: 1 | BA13: =SUM(B13:AY13) -> 5 | BC13: 1
A14: BANKSY | D14: 1 | I14: 1 | AC14: 2 | BA14: =SUM(B14:AY14) -> 4 | BB14: 1
A15: BRUCE | W15: 1 | AB15: 1 | AD15: 2 | BA15: =SUM(B15:AY15) -> 4 | BC15: 1
A16: KRYTON | C16: 1 | AD16: 2 | BA16: =SUM(B16:AY16) -> 3 | BC16: 2
A17: FATHER TED | L17: 1 | M17: 1 | Q17: 1 | BA17: =SUM(B17:AY17) -> 3 | BC17: 1
A18: DUNCAN | D18: 1 | H18: 1 | I18: 1 | BA18: =SUM(B18:AY18) -> 3
A19: PRESTON | D19: 1 | R19: 1 | U19: 1 | BA19: =SUM(B19:AY19) -> 3
A20: TOY BOY | D20: 2 | BA20: =SUM(B20:AY20) -> 2 | BB20: 1
A21: ARTIST | L21: 1 | P21: 1 | BA21: =SUM(B21:AY21) -> 2 | BC21: 2
A22: INSPECTOR GADGET | F22: 1 | I22: 1 | BA22: =SUM(B22:AY22) -> 2 | BC22: 1
A23: STEPTOE | W23: 2 | BA23: =SUM(B23:AY23) -> 2 | BC23: 1
A24: PHANTOM | E24: 1 | K24: 1 | BA24: =SUM(B24:AY24) -> 2
A25: MICK | R25: 1 | T25: 1 | BA25: =SUM(B25:AY25) -> 2
A26: MAMAS | C26: 1 | BA26: =SUM(B26:AY26) -> 1 | BC26: 1
A27: STEPHEN J | C27: 1 | BA27: =SUM(B27:AY27) -> 1 | BC27: 1
A28: WILSON | C28: 1 | BA28: =SUM(B28:AY28) -> 1 | BC28: 1
A29: CARLOS | N29: 1 | BA29: =SUM(B29:AY29) -> 1
A30: GUEST | M30: 1 | BA30: =SUM(B30:AY30) -> 1
A31: MOO | Y31: 1 | BA31: =SUM(B31:AY31) -> 1
A32: DOM | AD32: 1 | BA32: =SUM(B32:AY32) -> 1
A33: GOBBY | BA33: =SUM(B33:AY33) -> 0
A34: CARZOLA | BA34: =SUM(B34:AY34) -> 0
A35: DOBBO | BA35: =SUM(B35:AY35) -> 0
A38: # PLAYERS | B38: ='League Table'!B42 -> 0 | C38: ='League Table'!C42 -> 18 | D38: ='League Table'!D42 -> 14 | E38: ='League Table'!E42 -> 18 | F38: ='League Table'!F42 -> 12 | G38: ='League Table'!G42 -> 12 | H38: ='League Table'!H42 -> 14 | I38: ='League Table'!I42 -> 20 | ... AV38: ='League Table'!AV42 -> 0
A40: # VOTES | B40: =SUM(B3:B36) -> 0 | C40: =SUM(C3:C36) -> 5 | D40: =SUM(D3:D36) -> 6 | E40: =SUM(E3:E36) -> 7 | F40: =SUM(F3:F36) -> 3 | G40: =SUM(G3:G36) -> 3 | H40: =SUM(H3:H36) -> 6 | I40: =SUM(I3:I36) -> 6 | ... AV40: =SUM(AV3:AV36) -> 0

Sheet Goals
A1: MARLOW DUKES 2026- Goals
A3: PLAYER | B3: WK 1 | C3: WK 2 | D3: WK 3 | E3: WK 4 | F3: WK 5 | G3: WK 6 | H3: WK 7 | I3: WK 8 | J3: WK 9 | K3: WK 10 | L3: WK 11 | M3: WK 12 | N3: WK 13 | O3: WK 14 | P3: WK 15 | Q3: WK 16 | R3: WK 17 | S3: WK 18 | T3: WK 19 | U3: WK 20 | V3: WK 21 | W3: WK 22 | X3: WK 23 | Y3: WK 24 | Z3: WK 25 | AA3: WK 26 | AB3: WK 27 | AC3: WK 28 | AD3: WK 29 | AE3: WK 30 | AF3: WK 31 | AG3: WK 32 | AH3: WK 33 | AI3: WK 34 | AJ3: WK 35 | AK3: WK 36 | AL3: WK 37 | AM3: WK 38 | AN3: WK 39 | AO3: WK 40 | AP3: WK 41 | AQ3: WK 42 | AR3: WK 43 | AS3: WK 44 | AT3: WK 45 | AU3: WK 46 | AV3: WK 47 | AW3: WK 48 | AX3: WK 49 | AY3: WK 50 | BA3: TOTAL
A5: KERMIT | C5: 1 | F5: 2 | G5: 1 | H5: 3 | I5: 1 | J5: 1 | N5: 3 | P5: 1 | R5: 3 | U5: 1 | AB5: 2 | AD5: 1 | BA5: =SUM(B5:AY5) -> 20
A6: TONY W | J6: 1 | M6: 2 | P6: 3 | Q6: 2 | V6: 3 | AA6: 2 | AC6: 2 | AD6: 3 | AE6: 1 | BA6: =SUM(B6:AY6) -> 19
A7: DUNCAN | D7: 2 | G7: 1 | H7: 2 | K7: 1 | L7: 1 | M7: 1 | N7: 1 | O7: 1 | W7: 1 | AB7: 1 | AD7: 1 | AF7: 4 | BA7: =SUM(B7:AY7) -> 17
A8: IAN | G8: 1 | I8: 1 | J8: 3 | L8: 4 | N8: 2 | Q8: 1 | AB8: 1 | AC8: 1 | BA8: =SUM(B8:AY8) -> 14
A9: FLO | I9: 1 | O9: 1 | V9: 2 | W9: 2 | AA9: 1 | AB9: 3 | AE9: 1 | BA9: =SUM(B9:AY9) -> 11
A10: SWAMPY | H10: 2 | M10: 1 | Q10: 1 | R10: 4 | W10: 1 | AB10: 1 | AD10: 1 | BA10: =SUM(B10:AY10) -> 11
A11: ZIGZAG | G11: 1 | K11: 2 | M11: 1 | Q11: 1 | W11: 1 | Y11: 1 | AB11: 2 | AC11: 1 | AF11: 1 | BA11: =SUM(B11:AY11) -> 11
A12: BROWN NOSE | G12: 3 | L12: 1 | W12: 1 | AA12: 1 | AB12: 1 | AC12: 1 | AD12: 1 | BA12: =SUM(B12:AY12) -> 9
A13: POSH CHRIS | J13: 4 | N13: 1 | P13: 1 | Q13: 1 | R13: 2 | BA13: =SUM(B13:AY13) -> 9
A14: OG | K14: 1 | L14: 1 | R14: 1 | AA14: 1 | AD14: 1 | BA14: =SUM(B14:AY14) -> 5
A15: GOBBY | C15: 1 | AD15: 2 | BA15: =SUM(B15:AY15) -> 3
A16: GUEST | N16: 1 | V16: 1 | AF16: 1 | BA16: =SUM(B16:AY16) -> 3
A17: DOM | AE17: 1 | AF17: 1 | BA17: =SUM(B17:AY17) -> 2
A18: PHANTOM | L18: 2 | BA18: =SUM(B18:AY18) -> 2
A19: DITCH | R19: 1 | BA19: =SUM(B19:AY19) -> 1
A20: FATHER TED | L20: 1 | BA20: =SUM(B20:AY20) -> 1
A21: INSPECTOR GADGET | M21: 1 | BA21: =SUM(B21:AY21) -> 1
A22: KRYTON | N22: 1 | BA22: =SUM(B22:AY22) -> 1
A23: MAMAS | C23: 1 | BA23: =SUM(B23:AY23) -> 1
A24: PRESTON | N24: 1 | BA24: =SUM(B24:AY24) -> 1
A25: STEPHEN P | C25: 1 | BA25: =SUM(B25:AY25) -> 1
A26: STEPTOE | AC26: 1 | BA26: =SUM(B26:AY26) -> 1
A27: WILSON | G27: 1 | BA27: =SUM(B27:AY27) -> 1
A28: ARTIST | BA28: =SUM(B28:AY28) -> 0
A29: BANKSY | BA29: =SUM(B29:AY29) -> 0
A30: BRUCE | BA30: =SUM(B30:AY30) -> 0
A31: CAPTAIN KIRK | BA31: =SUM(B31:AY31) -> 0
A32: CARLOS | BA32: =SUM(B32:AY32) -> 0
A33: CARZOLA | BA33: =SUM(B33:AY33) -> 0
A34: DWARF | BA34: =SUM(B34:AY34) -> 0
A35: MOO | BA35: =SUM(B35:AY35) -> 0
A36: SONESY | BA36: =SUM(B36:AY36) -> 0
A37: TOY BOY | BA37: =SUM(B37:AY37) -> 0
A39: Total | B39: =SUM(B5:B37) -> 0 | C39: =SUM(C5:C37) -> 4 | D39: =SUM(D5:D37) -> 2 | E39: =SUM(E5:E37) -> 0 | F39: =SUM(F5:F37) -> 2 | G39: =SUM(G5:G37) -> 8 | H39: =SUM(H5:H37) -> 7 | I39: =SUM(I5:I37) -> 3 | ... AY39: =SUM(AY5:AY37) -> 0 | BA39: =SUM(B39:AZ39) -> 145

Sheet Board Room
A1: Week | B1: Captain | C1: Result | D1: Called In 1 | E1: Called In 2
A3: 1 | B3: Void | C3: Void | D3: Void | E3: Void
A4: 2 | B4: Phantom - Brown Nose | C4: Drew 2-2 | D4: Void | E4: Void
A5: 3 | B5: Kermit - Idiot | C5: Lost 0-2 | D5: Gadget | E5: Martin
A6: 4 | B6: Wilson - ZigZag | C6: Drew 0-0 | D6: Void | E6: Void
A7: 5 | B7: Posh - Brown Nose | C7: Lost 0-2 | D7: Duncan | E7: Void | H7: Chosen | K7: As Captain | M7: Total
A8: 6 | B8: Bruce - Preston | C8: Lost 3-5 | D8: Posh | E8: Void
A9: 7 | B9: Kryton - Duncan | C9: Lost 3-4 | D9: Preston | E9: Bruce | H9: Bruce | I9: 3 | K9: Kermit | L9: 3 | M9: Phantom | N9: 5
A10: 8 | B10: Gobby - Gadget | C10: Lost 1-2 | D10: Stephen J | E10: Duncan | H10: Duncan | I10: 3 | K10: Swampy | L10: 2 | M10: Kermit | N10: 5
A11: 9 | B11: Father Ted - Captain Kirk | C11: Lost 4-5 | D11: Phantom | E11: Tony | H11: Preston | I11: 3 | K11: Flo | L11: 2 | M11: Bruce | N11: 4
A12: 10 | B12: Dwarf v Artist | C12: Drew 2-2 | D12: Void | E12: Void | H12: Brown Nose | I12: 3 | K12: Posh | M12: Duncan | N12: 3
A13: 11 | B13: Flo - Sonesy | C13: Lost 3-7 | D13: Artist | E13: Bruce | H13: Phantom | I13: 2 | K13: Bruce | M13: Flo | N13: 3
A14: 12 | B14: Moo v Carzola | C14: Lost 2-4 | D14: Brown Nose | E14: Gobby | H14: Espen | I14: 2 | K14: Kryton | M14: Preston | N14: 3
A15: 13 | B15: Swampy - Carlos | C15: Lost 4-6 | D15: Preston | E15: Bruce | H15: Kermit | I15: 2 | K15: Gobby | M15: Brown Nose | N15: 3
A16: 14 | B16: Posh v Preston | C16: Drew 1-1 | D16: Void | E16: Void | H16: Gobby | I16: 2 | K16: Father Ted | M16: Gobby | N16: 3
A17: 15 | B17: Banksy v Tony W | C17: Lost 0-5 | D17: Captain Kirk | E17: Phantom | H17: Gadget | K17: Moo | M17: Tony W | N17: 3
A18: 16 | B18: Father Ted v Phantom | C18: Lost 1-5 | D18: ZigZag | E18: Espen | H18: Martin | K18: Banksy | M18: Posh | N18: 2
A19: 17 | B19: Kermit v Bruce | C19: Lost 4-7 | D19: Phantom | H19: Posh | K19: Father Ted | M19: Father Ted | N19: 2
A20: 18 | B20: Void | C20: Void | D20: Void | E20: Void | H20: Stephen J | K20: Preston | M20: Swampy | N20: 2
A21: 19 | B21: ZigZag v Duncan | C21: Drew | D21: Void | E21: Void | H21: Artist | K21: Phantom | M21: Kryton | N21: 2
A22: 20 | B22: Void | C22: Void | D22: Void | E22: Void | H22: Captain Kirk | K22: Tony W | M22: Gadget | N22: 1
A23: 21 | B23: Sones v Carzola | C23: Drew 3-3 | D23: Void | E23: Void | H23: ZigZag | M23: Martin | N23: 1
A24: 22 | B24: Gobby v Idiot | C24: Drew 3-3 | D24: Void | E24: Void | H24: Tony W | M24: Stephen J | N24: 1
A25: 23 | B25: Void | C25: Void | D25: Void | E25: Void | H25: Kryton | M25: Artist | N25: 1
A26: 24 | B26: Swampy - Artist | C26: Lost 0-1 | D26: Duncan | E26: Espen | H26: Mamas | M26: Moo | N26: 1
A27: 25 | B27: Void | C27: Void | D27: Void | E27: Void | M27: Banksy | N27: 1
A28: 26 | B28: Preston - Bruce | C28: Lost 1-4 | D28: Kermit | E28: Brown Nose | M28: Captain Kirk | N28: 1
A29: 27 | B29: Flo - Posh | C29: Lost 5-7 | M29: ZigZag | N29: 1
A30: 28 | B30: Phantom - Banksy | C30: Lost 2-4 | D30: Preston | M30: Mamas | N30: 1
A31: 29 | B31: Idiot - Kryton | C31: Drew 5-5 | D31: Void | E31: Void
A32: 30 | B32: Kermit - Captain Kirk | C32: Lost 1-2 | D32: Kryton | E32: Tony W
A33: 31 | B33: Tony W - Dwarf | C33: Lost 1-6 | D33: Gobby | E33: Mamas
A34: 32
A35: 33
A36: 34
A37: 35
A38: 36
A39: 37
A40: 38
A41: 39
...
